<?xml version="1.0"?>
<robot name="xdog" xmlns:xacro="http://www.ros.org/wiki/xacro">

  <xacro:property name="motor_torque" value="0.30"/>
  <xacro:property name="motor_vec" value="0.1256"/>
  <xacro:property name="motor_damp" value="0.1"/>
  <xacro:property name="motor_fric" value="0.1"/>
  
  <link name="base_link">
    </link>

  <joint name="base_link_joint" type="fixed">
    <origin
      xyz="0 0 0.2"
      rpy="0 0 0" />
    <parent link="base_link"/>
    <child link="body_link"/>
  </joint>

  <link
    name="body_link">
    <inertial>
      <origin
        xyz="0.0100797468384241 -6.69343053205651E-15 0.014671259999792"
        rpy="0 0 0" />
      <mass
        value="0.144204255125478" />
      <inertia
        ixx="1.68530851280875E-06"
        ixy="6.48991765659259E-18"
        ixz="-3.26289108002853E-06"
        iyy="0.000221482596538362"
        iyz="1.9419753606534E-18"
        izz="0.000219797288025553" />
    </inertial>
    <visual>
      <origin
        xyz="0 0 0"
        rpy="0 0 0" />
      <geometry>
        <mesh
          filename="package://xdog_description/meshes/body_link.STL" />
      </geometry>
      <material
        name="">
        <color
          rgba="1 1 1 0.32" />
      </material>
    </visual>
    <collision>
      <origin
        xyz="0 0 0"
        rpy="0 0 0" />
      <geometry>
        <mesh
          filename="package://xdog_description/meshes/body_link.STL" />
      </geometry>
    </collision>
  </link>
  <link
    name="Link_13">
    <inertial>
      <origin
        xyz="0.00589211277664583 -0.00486711947882101 -0.00589211281765438"
        rpy="0 0 0" />
      <mass
        value="0.0222474344540392" />
      <inertia
        ixx="1.05777822701638E-06"
        ixy="1.75424012982505E-07"
        ixz="-9.25745238901298E-08"
        iyy="8.38710703025697E-07"
        iyz="1.01496626639778E-07"
        izz="1.05777822724898E-06" />
    </inertial>
    <visual>
      <origin
        xyz="0 0 0"
        rpy="0 0 0" />
      <geometry>
        <mesh
          filename="package://xdog_description/meshes/Link_13.STL" />
      </geometry>
      <material
        name="">
        <color
          rgba="1 1 1 0.32" />
      </material>
    </visual>
    <collision>
      <origin
        xyz="0 0 0"
        rpy="0 0 0" />
      <geometry>
        <mesh
          filename="package://xdog_description/meshes/Link_13.STL" />
      </geometry>
    </collision>
  </link>
  <joint
    name="Joint_13"
    type="revolute">
    <origin
      xyz="0.083446 0.05 0"
      rpy="1.5708 -8.6736E-18 1.5708" />
    <parent
      link="body_link" />
    <child
      link="Link_13" />
    <axis
      xyz="0 0 -1" />
    <limit
      lower="-6.28"
      upper="6.28"
      effort="0"
      velocity="0" />
    <dynamics
      damping="0.1"
      friction="0.1" />
    <safety_controller
      soft_upper="3.14"
      soft_lower="-3.14"
      k_velocity="0" />
  </joint>
  <link
    name="Link_12">
    <inertial>
      <origin
        xyz="0.032500000000006 -3.70536934468646E-15 0.00597908298070465"
        rpy="0 0 0" />
      <mass
        value="0.0122823538406087" />
      <inertia
        ixx="4.27588858132138E-06"
        ixy="2.91835280501246E-32"
        ixz="-3.30206050213601E-19"
        iyy="4.27588858132138E-06"
        iyz="3.51688648961631E-19"
        izz="5.84834157753854E-32" />
    </inertial>
    <visual>
      <origin
        xyz="0 0 0"
        rpy="0 0 0" />
      <geometry>
        <mesh
          filename="package://xdog_description/meshes/Link_12.STL" />
      </geometry>
      <material
        name="">
        <color
          rgba="1 1 1 0.32" />
      </material>
    </visual>
    <collision>
      <origin
        xyz="0 0 0"
        rpy="0 0 0" />
      <geometry>
        <mesh
          filename="package://xdog_description/meshes/Link_12.STL" />
      </geometry>
    </collision>
  </link>
  <joint
    name="Joint_12"
    type="revolute">
    <origin
      xyz="0 -0.012087 0"
      rpy="-1.5708 -5.5515E-17 -1.5708" />
    <parent
      link="Link_13" />
    <child
      link="Link_12" />
    <axis
      xyz="0 0 -1" />
    <limit
      lower="-6.28"
      upper="6.28"
      effort="0"
      velocity="0" />
    <dynamics
      damping="0.1"
      friction="0.1" />
    <safety_controller
      soft_upper="3.14"
      soft_lower="-3.14"
      k_velocity="0" />
  </joint>
  <link
    name="Link_11">
    <inertial>
      <origin
        xyz="0.0245886888409639 -0.00138827725185643 0.00591127232774293"
        rpy="0 0 0" />
      <mass
        value="0.0211642503887348" />
      <inertia
        ixx="3.69491793613372E-07"
        ixy="6.2268804555493E-08"
        ixz="5.38338810002208E-07"
        iyy="5.17389351902356E-06"
        iyz="-1.43507075395677E-08"
        izz="4.81354541498219E-06" />
    </inertial>
    <visual>
      <origin
        xyz="0 0 0"
        rpy="0 0 0" />
      <geometry>
        <mesh
          filename="package://xdog_description/meshes/Link_11.STL" />
      </geometry>
      <material
        name="">
        <color
          rgba="1 1 1 0.32" />
      </material>
    </visual>
    <collision>
      <origin
        xyz="0 0 0"
        rpy="0 0 0" />
      <geometry>
        <mesh
          filename="package://xdog_description/meshes/Link_11.STL" />
      </geometry>
    </collision>
  </link>
  <joint
    name="Joint_11"
    type="revolute">
    <origin
      xyz="0.065 0 0"
      rpy="-2.9633E-16 1.9559E-16 1.2326E-32" />
    <parent
      link="Link_12" />
    <child
      link="Link_11" />
    <axis
      xyz="0 0 -1" />
    <limit
      lower="-6.28"
      upper="6.28"
      effort="0"
      velocity="0" />
    <dynamics
      damping="0.1"
      friction="0.1" />
    <safety_controller
      soft_upper="3.14"
      soft_lower="-3.14"
      k_velocity="0" />
  </joint>
  <link
    name="Link_23">
    <inertial>
      <origin
        xyz="-0.00589211278446432 -0.00486712588929642 -0.00589211278452656"
        rpy="0 0 0" />
      <mass
        value="0.0222474343441445" />
      <inertia
        ixx="1.06158508682637E-06"
        ixy="-1.75490176065455E-07"
        ixz="9.25745239302861E-08"
        iyy="8.38710703268278E-07"
        iyz="1.01562555057632E-07"
        izz="1.06158508682598E-06" />
    </inertial>
    <visual>
      <origin
        xyz="0 0 0"
        rpy="0 0 0" />
      <geometry>
        <mesh
          filename="package://xdog_description/meshes/Link_23.STL" />
      </geometry>
      <material
        name="">
        <color
          rgba="1 1 1 0.32" />
      </material>
    </visual>
    <collision>
      <origin
        xyz="0 0 0"
        rpy="0 0 0" />
      <geometry>
        <mesh
          filename="package://xdog_description/meshes/Link_23.STL" />
      </geometry>
    </collision>
  </link>
  <joint
    name="Joint_23"
    type="revolute">
    <origin
      xyz="0.083446 -0.05 0"
      rpy="1.5708 -3.4694E-18 1.5708" />
    <parent
      link="body_link" />
    <child
      link="Link_23" />
    <axis
      xyz="0 0 -1" />
    <limit
      lower="-6.28"
      upper="6.28"
      effort="0"
      velocity="0" />
    <dynamics
      damping="0.1"
      friction="0.1" />
    <safety_controller
      soft_upper="3.14"
      soft_lower="-3.14"
      k_velocity="0" />
  </joint>
  <link
    name="Link_22">
    <inertial>
      <origin
        xyz="0.0325000000000334 -7.03603841856193E-15 -0.00597908298070209"
        rpy="0 0 0" />
      <mass
        value="0.0122823538406087" />
      <inertia
        ixx="4.27588858132137E-06"
        ixy="-2.99371139685498E-32"
        ixz="3.37507422987452E-19"
        iyy="4.27588858132137E-06"
        iyz="3.54070762138337E-19"
        izz="5.99474686297144E-32" />
    </inertial>
    <visual>
      <origin
        xyz="0 0 0"
        rpy="0 0 0" />
      <geometry>
        <mesh
          filename="package://xdog_description/meshes/Link_22.STL" />
      </geometry>
      <material
        name="">
        <color
          rgba="1 1 1 0.32" />
      </material>
    </visual>
    <collision>
      <origin
        xyz="0 0 0"
        rpy="0 0 0" />
      <geometry>
        <mesh
          filename="package://xdog_description/meshes/Link_22.STL" />
      </geometry>
    </collision>
  </link>
  <joint
    name="Joint_22"
    type="revolute">
    <origin
      xyz="0 -0.012087 0"
      rpy="-1.5708 -2.2205E-16 -1.5708" />
    <parent
      link="Link_23" />
    <child
      link="Link_22" />
    <axis
      xyz="0 0 -1" />
    <limit
      lower="-6.28"
      upper="6.28"
      effort="0"
      velocity="0" />
    <dynamics
      damping="0.1"
      friction="0.1" />
    <safety_controller
      soft_upper="3.14"
      soft_lower="-3.14"
      k_velocity="0" />
  </joint>
  <link
    name="Link_21">
    <inertial>
      <origin
        xyz="0.024583786441454 -0.00139405658271938 -0.00591062094058505"
        rpy="0 0 0" />
      <mass
        value="0.0211575776279215" />
      <inertia
        ixx="3.69505650415199E-07"
        ixy="5.89881536992127E-08"
        ixz="-5.38512272494569E-07"
        iyy="5.17472254572913E-06"
        iyz="1.43045490492435E-08"
        izz="4.81430144751336E-06" />
    </inertial>
    <visual>
      <origin
        xyz="0 0 0"
        rpy="0 0 0" />
      <geometry>
        <mesh
          filename="package://xdog_description/meshes/Link_21.STL" />
      </geometry>
      <material
        name="">
        <color
          rgba="1 1 1 0.32" />
      </material>
    </visual>
    <collision>
      <origin
        xyz="0 0 0"
        rpy="0 0 0" />
      <geometry>
        <mesh
          filename="package://xdog_description/meshes/Link_21.STL" />
      </geometry>
    </collision>
  </link>
  <joint
    name="Joint_21"
    type="revolute">
    <origin
      xyz="0.065 0 0"
      rpy="-5.2549E-13 2.5997E-13 1.1102E-16" />
    <parent
      link="Link_22" />
    <child
      link="Link_21" />
    <axis
      xyz="0 0 -1" />
    <limit
      lower="-6.28"
      upper="6.28"
      effort="0"
      velocity="0" />
    <dynamics
      damping="0.1"
      friction="0.1" />
    <safety_controller
      soft_upper="3.14"
      soft_lower="-3.14"
      k_velocity="0" />
  </joint>
  <link
    name="Link_33">
    <inertial>
      <origin
        xyz="-0.00589210844151958 -0.00486712091967801 -0.00589211564372161"
        rpy="0 0 0" />
      <mass
        value="0.0222474249737409" />
      <inertia
        ixx="1.06158381911298E-06"
        ixy="-1.75489104820231E-07"
        ixz="9.25739533220922E-08"
        iyy="8.38709582675674E-07"
        iyz="1.01562035051929E-07"
        izz="1.06158301413829E-06" />
    </inertial>
    <visual>
      <origin
        xyz="0 0 0"
        rpy="0 0 0" />
      <geometry>
        <mesh
          filename="package://xdog_description/meshes/Link_33.STL" />
      </geometry>
      <material
        name="">
        <color
          rgba="1 1 1 0.32" />
      </material>
    </visual>
    <collision>
      <origin
        xyz="0 0 0"
        rpy="0 0 0" />
      <geometry>
        <mesh
          filename="package://xdog_description/meshes/Link_33.STL" />
      </geometry>
    </collision>
  </link>
  <joint
    name="Joint_33"
    type="revolute">
    <origin
      xyz="-0.071954 -0.05 0"
      rpy="1.5708 1.191E-26 1.5708" />
    <parent
      link="body_link" />
    <child
      link="Link_33" />
    <axis
      xyz="0 0 -1" />
    <limit
      lower="-6.28"
      upper="6.28"
      effort="0"
      velocity="0" />
    <dynamics
      damping="0.1"
      friction="0.1" />
    <safety_controller
      soft_upper="3.14"
      soft_lower="-3.14"
      k_velocity="0" />
  </joint>
  <link
    name="Link_32">
    <inertial>
      <origin
        xyz="0.032500000000006 -7.27196081129478E-15 -0.00597908298070463"
        rpy="0 0 0" />
      <mass
        value="0.0122823538406087" />
      <inertia
        ixx="4.27588858132138E-06"
        ixy="-2.98429333611619E-32"
        ixz="3.37477792960342E-19"
        iyy="4.27588858132138E-06"
        iyz="3.52499937396855E-19"
        izz="5.97857672413404E-32" />
    </inertial>
    <visual>
      <origin
        xyz="0 0 0"
        rpy="0 0 0" />
      <geometry>
        <mesh
          filename="package://xdog_description/meshes/Link_32.STL" />
      </geometry>
      <material
        name="">
        <color
          rgba="1 1 1 0.32" />
      </material>
    </visual>
    <collision>
      <origin
        xyz="0 0 0"
        rpy="0 0 0" />
      <geometry>
        <mesh
          filename="package://xdog_description/meshes/Link_32.STL" />
      </geometry>
    </collision>
  </link>
  <joint
    name="Joint_32"
    type="revolute">
    <origin
      xyz="0 -0.012087 0"
      rpy="-1.5708 -1.6654E-16 -1.5708" />
    <parent
      link="Link_33" />
    <child
      link="Link_32" />
    <axis
      xyz="0 0 -1" />
    <limit
      lower="-6.28"
      upper="6.28"
      effort="0"
      velocity="0" />
    <dynamics
      damping="0.1"
      friction="0.1" />
    <safety_controller
      soft_upper="3.14"
      soft_lower="-3.14"
      k_velocity="0" />
  </joint>
  <link
    name="Link_31">
    <inertial>
      <origin
        xyz="0.024583798575402 -0.00139405515632768 -0.0059106159242525"
        rpy="0 0 0" />
      <mass
        value="0.0211575679729923" />
      <inertia
        ixx="3.69504604037116E-07"
        ixy="5.89887459631398E-08"
        ixz="-5.38509568976573E-07"
        iyy="5.17471503754709E-06"
        iyz="1.43048206907216E-08"
        izz="4.8142950269045E-06" />
    </inertial>
    <visual>
      <origin
        xyz="0 0 0"
        rpy="0 0 0" />
      <geometry>
        <mesh
          filename="package://xdog_description/meshes/Link_31.STL" />
      </geometry>
      <material
        name="">
        <color
          rgba="1 1 1 0.32" />
      </material>
    </visual>
    <collision>
      <origin
        xyz="0 0 0"
        rpy="0 0 0" />
      <geometry>
        <mesh
          filename="package://xdog_description/meshes/Link_31.STL" />
      </geometry>
    </collision>
  </link>
  <joint
    name="Joint_31"
    type="revolute">
    <origin
      xyz="0.065 0 0"
      rpy="-5.2564E-13 2.6012E-13 5.5511E-17" />
    <parent
      link="Link_32" />
    <child
      link="Link_31" />
    <axis
      xyz="0 0 -1" />
    <limit
      lower="-6.28"
      upper="6.28"
      effort="0"
      velocity="0" />
    <dynamics
      damping="0.1"
      friction="0.1" />
    <safety_controller
      soft_upper="3.14"
      soft_lower="-3.14"
      k_velocity="0" />
  </joint>
  <link
    name="Link_43">
    <inertial>
      <origin
        xyz="0.00589211278447819 -0.0048671194257208 -0.00589211278451113"
        rpy="0 0 0" />
      <mass
        value="0.0222474343441445" />
      <inertia
        ixx="1.05777821597198E-06"
        ixy="1.75424014223683E-07"
        ixz="-9.25745239301222E-08"
        iyy="8.38710703269563E-07"
        iyz="1.01496631855862E-07"
        izz="1.05777821597202E-06" />
    </inertial>
    <visual>
      <origin
        xyz="0 0 0"
        rpy="0 0 0" />
      <geometry>
        <mesh
          filename="package://xdog_description/meshes/Link_43.STL" />
      </geometry>
      <material
        name="">
        <color
          rgba="1 1 1 0.32" />
      </material>
    </visual>
    <collision>
      <origin
        xyz="0 0 0"
        rpy="0 0 0" />
      <geometry>
        <mesh
          filename="package://xdog_description/meshes/Link_43.STL" />
      </geometry>
    </collision>
  </link>
  <joint
    name="Joint_43"
    type="revolute">
    <origin
      xyz="-0.071954 0.05 0"
      rpy="1.5708 -1.1949E-26 1.5708" />
    <parent
      link="body_link" />
    <child
      link="Link_43" />
    <axis
      xyz="0 0 -1" />
    <limit
      lower="-6.28"
      upper="6.28"
      effort="0"
      velocity="0" />
    <dynamics
      damping="0.1"
      friction="0.1" />
    <safety_controller
      soft_upper="3.14"
      soft_lower="-3.14"
      k_velocity="0" />
  </joint>
  <link
    name="Link_42">
    <inertial>
      <origin
        xyz="0.032500000000006 -3.77475828372553E-15 0.0059790829807046"
        rpy="0 0 0" />
      <mass
        value="0.0122823538406087" />
      <inertia
        ixx="4.27588858132138E-06"
        ixy="2.93708078100976E-32"
        ixz="-3.38120358699033E-19"
        iyy="4.27588858132138E-06"
        iyz="3.45837985177173E-19"
        izz="5.87696360128622E-32" />
    </inertial>
    <visual>
      <origin
        xyz="0 0 0"
        rpy="0 0 0" />
      <geometry>
        <mesh
          filename="package://xdog_description/meshes/Link_42.STL" />
      </geometry>
      <material
        name="">
        <color
          rgba="1 1 1 0.32" />
      </material>
    </visual>
    <collision>
      <origin
        xyz="0 0 0"
        rpy="0 0 0" />
      <geometry>
        <mesh
          filename="package://xdog_description/meshes/Link_42.STL" />
      </geometry>
    </collision>
  </link>
  <joint
    name="Joint_42"
    type="revolute">
    <origin
      xyz="0 -0.012087 0"
      rpy="-1.5708 -1.6654E-16 -1.5708" />
    <parent
      link="Link_43" />
    <child
      link="Link_42" />
    <axis
      xyz="0 0 -1" />
    <limit
      lower="-6.28"
      upper="6.28"
      effort="0"
      velocity="0" />
    <dynamics
      damping="0.1"
      friction="0.1" />
    <safety_controller
      soft_upper="3.14"
      soft_lower="-3.14"
      k_velocity="0" />
  </joint>
  <link
    name="Link_41">
    <inertial>
      <origin
        xyz="0.0245886903668074 -0.00138827750846154 0.00591127172128426"
        rpy="0 0 0" />
      <mass
        value="0.0211642494468741" />
      <inertia
        ixx="3.69491649086748E-07"
        ixy="6.22686910423853E-08"
        ixz="5.38338441295405E-07"
        iyy="5.17389245867672E-06"
        iyz="-1.43506635566749E-08"
        izz="4.81354449246953E-06" />
    </inertial>
    <visual>
      <origin
        xyz="0 0 0"
        rpy="0 0 0" />
      <geometry>
        <mesh
          filename="package://xdog_description/meshes/Link_41.STL" />
      </geometry>
      <material
        name="">
        <color
          rgba="1 1 1 0.32" />
      </material>
    </visual>
    <collision>
      <origin
        xyz="0 0 0"
        rpy="0 0 0" />
      <geometry>
        <mesh
          filename="package://xdog_description/meshes/Link_41.STL" />
      </geometry>
    </collision>
  </link>
  <joint
    name="Joint_41"
    type="revolute">
    <origin
      xyz="0.065 0 0"
      rpy="-5.8578E-17 1.0149E-16 0" />
    <parent
      link="Link_42" />
    <child
      link="Link_41" />
    <axis
      xyz="0 0 -1" />
    <limit
      lower="-6.28"
      upper="6.28"
      effort="0"
      velocity="0" />
    <dynamics
      damping="0.1"
      friction="0.1" />
    <safety_controller
      soft_upper="3.14"
      soft_lower="-3.14"
      k_velocity="0" />
  </joint>


</robot>
